Workbook

Sheet train
A1: PassengerId | B1: Survived | C1: Pclass | D1: Name | E1: Sex | F1: Age | G1: SibSp | H1: Parch | I1: Ticket | J1: Fare | K1: Cabin | L1: Embarked | M1: Age Group
A2: 1 | B2: 0 | C2: 3 | D2: Braund, Mr. Owen Harris | E2: male | F2: 22 | G2: 1 | H2: 0 | I2: A/5 21171 | J2: 7.25 | K2: Unknown | L2: S | M2: =IF(F2<13,"Child",IF(F2<20,"Teenager",IF(F2<40,"Adult",IF(F2<60,"Middle Age","Senior")))) -> Adult
A3: 2 | B3: 1 | C3: 1 | D3: Cumings, Mrs. John Bradley (Florence Briggs Thayer) | E3: female | F3: 38 | G3: 1 | H3: 0 | I3: PC 17599 | J3: 71.2833 | K3: C85 | L3: C | M3: =IF(F3<13,"Child",IF(F3<20,"Teenager",IF(F3<40,"Adult",IF(F3<60,"Middle Age","Senior")))) -> Adult
A4: 3 | B4: 1 | C4: 3 | D4: Heikkinen, Miss. Laina | E4: female | F4: 26 | G4: 0 | H4: 0 | I4: STON/O2. 3101282 | J4: 7.925 | K4: Unknown | L4: S | M4: =IF(F4<13,"Child",IF(F4<20,"Teenager",IF(F4<40,"Adult",IF(F4<60,"Middle Age","Senior")))) -> Adult
A5: 4 | B5: 1 | C5: 1 | D5: Futrelle, Mrs. Jacques Heath (Lily May Peel) | E5: female | F5: 35 | G5: 1 | H5: 0 | I5: 113803 | J5: 53.1 | K5: C123 | L5: S | M5: =IF(F5<13,"Child",IF(F5<20,"Teenager",IF(F5<40,"Adult",IF(F5<60,"Middle Age","Senior")))) -> Adult
A6: 5 | B6: 0 | C6: 3 | D6: Allen, Mr. William Henry | E6: male | F6: 35 | G6: 0 | H6: 0 | I6: 373450 | J6: 8.05 | K6: Unknown | L6: S | M6: =IF(F6<13,"Child",IF(F6<20,"Teenager",IF(F6<40,"Adult",IF(F6<60,"Middle Age","Senior")))) -> Adult
A7: 6 | B7: 0 | C7: 3 | D7: Moran, Mr. James | E7: male | F7: 28 | G7: 0 | H7: 0 | I7: 330877 | J7: 8.4583 | K7: Unknown | L7: Q | M7: =IF(F7<13,"Child",IF(F7<20,"Teenager",IF(F7<40,"Adult",IF(F7<60,"Middle Age","Senior")))) -> Adult
A8: 7 | B8: 0 | C8: 1 | D8: McCarthy, Mr. Timothy J | E8: male | F8: 54 | G8: 0 | H8: 0 | I8: 17463 | J8: 51.8625 | K8: E46 | L8: S | M8: =IF(F8<13,"Child",IF(F8<20,"Teenager",IF(F8<40,"Adult",IF(F8<60,"Middle Age","Senior")))) -> Middle Age
A9: 8 | B9: 0 | C9: 3 | D9: Palsson, Master. Gosta Leonard | E9: male | F9: 2 | G9: 3 | H9: 1 | I9: 349909 | J9: 21.075 | K9: Unknown | L9: S | M9: =IF(F9<13,"Child",IF(F9<20,"Teenager",IF(F9<40,"Adult",IF(F9<60,"Middle Age","Senior")))) -> Child
A10: 9 | B10: 1 | C10: 3 | D10: Johnson, Mrs. Oscar W (Elisabeth Vilhelmina Berg) | E10: female | F10: 27 | G10: 0 | H10: 2 | I10: 347742 | J10: 11.1333 | K10: Unknown | L10: S | M10: =IF(F10<13,"Child",IF(F10<20,"Teenager",IF(F10<40,"Adult",IF(F10<60,"Middle Age","Senior")))) -> Adult
A11: 10 | B11: 1 | C11: 2 | D11: Nasser, Mrs. Nicholas (Adele Achem) | E11: female | F11: 14 | G11: 1 | H11: 0 | I11: 237736 | J11: 30.0708 | K11: Unknown | L11: C | M11: =IF(F11<13,"Child",IF(F11<20,"Teenager",IF(F11<40,"Adult",IF(F11<60,"Middle Age","Senior")))) -> Teenager
A12: 11 | B12: 1 | C12: 3 | D12: Sandstrom, Miss. Marguerite Rut | E12: female | F12: 4 | G12: 1 | H12: 1 | I12: PP 9549 | J12: 16.7 | K12: G6 | L12: S | M12: =IF(F12<13,"Child",IF(F12<20,"Teenager",IF(F12<40,"Adult",IF(F12<60,"Middle Age","Senior")))) -> Child
A13: 12 | B13: 1 | C13: 1 | D13: Bonnell, Miss. Elizabeth | E13: female | F13: 58 | G13: 0 | H13: 0 | I13: 113783 | J13: 26.55 | K13: C103 | L13: S | M13: =IF(F13<13,"Child",IF(F13<20,"Teenager",IF(F13<40,"Adult",IF(F13<60,"Middle Age","Senior")))) -> Middle Age
A14: 13 | B14: 0 | C14: 3 | D14: Saundercock, Mr. William Henry | E14: male | F14: 20 | G14: 0 | H14: 0 | I14: A/5. 2151 | J14: 8.05 | K14: Unknown | L14: S | M14: =IF(F14<13,"Child",IF(F14<20,"Teenager",IF(F14<40,"Adult",IF(F14<60,"Middle Age","Senior")))) -> Adult
A15: 14 | B15: 0 | C15: 3 | D15: Andersson, Mr. Anders Johan | E15: male | F15: 39 | G15: 1 | H15: 5 | I15: 347082 | J15: 31.275 | K15: Unknown | L15: S | M15: =IF(F15<13,"Child",IF(F15<20,"Teenager",IF(F15<40,"Adult",IF(F15<60,"Middle Age","Senior")))) -> Adult
A16: 15 | B16: 0 | C16: 3 | D16: Vestrom, Miss. Hulda Amanda Adolfina | E16: female | F16: 14 | G16: 0 | H16: 0 | I16: 350406 | J16: 7.8542 | K16: Unknown | L16: S | M16: =IF(F16<13,"Child",IF(F16<20,"Teenager",IF(F16<40,"Adult",IF(F16<60,"Middle Age","Senior")))) -> Teenager
A17: 16 | B17: 1 | C17: 2 | D17: Hewlett, Mrs. (Mary D Kingcome) | E17: female | F17: 55 | G17: 0 | H17: 0 | I17: 248706 | J17: 16 | K17: Unknown | L17: S | M17: =IF(F17<13,"Child",IF(F17<20,"Teenager",IF(F17<40,"Adult",IF(F17<60,"Middle Age","Senior")))) -> Middle Age
A18: 17 | B18: 0 | C18: 3 | D18: Rice, Master. Eugene | E18: male | F18: 28 | G18: 4 | H18: 1 | I18: 382652 | J18: 29.125 | K18: Unknown | L18: Q | M18: =IF(F18<13,"Child",IF(F18<20,"Teenager",IF(F18<40,"Adult",IF(F18<60,"Middle Age","Senior")))) -> Adult
A19: 18 | B19: 1 | C19: 2 | D19: Williams, Mr. Charles Eugene | E19: male | F19: 28 | G19: 0 | H19: 0 | I19: 244373 | J19: 13 | K19: Unknown | L19: S | M19: =IF(F19<13,"Child",IF(F19<20,"Teenager",IF(F19<40,"Adult",IF(F19<60,"Middle Age","Senior")))) -> Adult
A20: 19 | B20: 0 | C20: 3 | D20: Vander Planke, Mrs. Julius (Emelia Maria Vandemoortele) | E20: female | F20: 31 | G20: 1 | H20: 0 | I20: 345763 | J20: 18 | K20: Unknown | L20: S | M20: =IF(F20<13,"Child",IF(F20<20,"Teenager",IF(F20<40,"Adult",IF(F20<60,"Middle Age","Senior")))) -> Adult
A21: 20 | B21: 1 | C21: 3 | D21: Masselmani, Mrs. Fatima | E21: female | F21: 28 | G21: 0 | H21: 0 | I21: 2649 | J21: 7.225 | K21: Unknown | L21: C | M21: =IF(F21<13,"Child",IF(F21<20,"Teenager",IF(F21<40,"Adult",IF(F21<60,"Middle Age","Senior")))) -> Adult
A22: 21 | B22: 0 | C22: 2 | D22: Fynney, Mr. Joseph J | E22: male | F22: 35 | G22: 0 | H22: 0 | I22: 239865 | J22: 26 | K22: Unknown | L22: S | M22: =IF(F22<13,"Child",IF(F22<20,"Teenager",IF(F22<40,"Adult",IF(F22<60,"Middle Age","Senior")))) -> Adult
A23: 22 | B23: 1 | C23: 2 | D23: Beesley, Mr. Lawrence | E23: male | F23: 34 | G23: 0 | H23: 0 | I23: 248698 | J23: 13 | K23: D56 | L23: S | M23: =IF(F23<13,"Child",IF(F23<20,"Teenager",IF(F23<40,"Adult",IF(F23<60,"Middle Age","Senior")))) -> Adult
A24: 23 | B24: 1 | C24: 3 | D24: McGowan, Miss. Anna "Annie" | E24: female | F24: 15 | G24: 0 | H24: 0 | I24: 330923 | J24: 8.0292 | K24: Unknown | L24: Q | M24: =IF(F24<13,"Child",IF(F24<20,"Teenager",IF(F24<40,"Adult",IF(F24<60,"Middle Age","Senior")))) -> Teenager
A25: 24 | B25: 1 | C25: 1 | D25: Sloper, Mr. William Thompson | E25: male | F25: 28 | G25: 0 | H25: 0 | I25: 113788 | J25: 35.5 | K25: A6 | L25: S | M25: =IF(F25<13,"Child",IF(F25<20,"Teenager",IF(F25<40,"Adult",IF(F25<60,"Middle Age","Senior")))) -> Adult
A26: 25 | B26: 0 | C26: 3 | D26: Palsson, Miss. Torborg Danira | E26: female | F26: 8 | G26: 3 | H26: 1 | I26: 349909 | J26: 21.075 | K26: Unknown | L26: S | M26: =IF(F26<13,"Child",IF(F26<20,"Teenager",IF(F26<40,"Adult",IF(F26<60,"Middle Age","Senior")))) -> Child
... A31: 30 | B31: 0 | C31: 3 | D31: Todoroff, Mr. Lalio | E31: male | F31: 28 | G31: 0 | H31: 0 | I31: 349216 | J31: 7.8958 | K31: Unknown | L31: S | M31: =IF(F31<13,"Child",IF(F31<20,"Teenager",IF(F31<40,"Adult",IF(F31<60,"Middle Age","Senior")))) -> Adult
A32: 31 | B32: 0 | C32: 1 | D32: Uruchurtu, Don. Manuel E | E32: male | F32: 40 | G32: 0 | H32: 0 | I32: PC 17601 | J32: 27.7208 | K32: Unknown | L32: C | M32: =IF(F32<13,"Child",IF(F32<20,"Teenager",IF(F32<40,"Adult",IF(F32<60,"Middle Age","Senior")))) -> Middle Age
A33: 32 | B33: 1 | C33: 1 | D33: Spencer, Mrs. William Augustus (Marie Eugenie) | E33: female | F33: 28 | G33: 1 | H33: 0 | I33: PC 17569 | J33: 146.5208 | K33: B78 | L33: C | M33: =IF(F33<13,"Child",IF(F33<20,"Teenager",IF(F33<40,"Adult",IF(F33<60,"Middle Age","Senior")))) -> Adult
A34: 33 | B34: 1 | C34: 3 | D34: Glynn, Miss. Mary Agatha | E34: female | F34: 28 | G34: 0 | H34: 0 | I34: 335677 | J34: 7.75 | K34: Unknown | L34: Q | M34: =IF(F34<13,"Child",IF(F34<20,"Teenager",IF(F34<40,"Adult",IF(F34<60,"Middle Age","Senior")))) -> Adult
A35: 34 | B35: 0 | C35: 2 | D35: Wheadon, Mr. Edward H | E35: male | F35: 66 | G35: 0 | H35: 0 | I35: C.A. 24579 | J35: 10.5 | K35: Unknown | L35: S | M35: =IF(F35<13,"Child",IF(F35<20,"Teenager",IF(F35<40,"Adult",IF(F35<60,"Middle Age","Senior")))) -> Senior
A36: 35 | B36: 0 | C36: 1 | D36: Meyer, Mr. Edgar Joseph | E36: male | F36: 28 | G36: 1 | H36: 0 | I36: PC 17604 | J36: 82.1708 | K36: Unknown | L36: C | M36: =IF(F36<13,"Child",IF(F36<20,"Teenager",IF(F36<40,"Adult",IF(F36<60,"Middle Age","Senior")))) -> Adult
A37: 36 | B37: 0 | C37: 1 | D37: Holverson, Mr. Alexander Oskar | E37: male | F37: 42 | G37: 1 | H37: 0 | I37: 113789 | J37: 52 | K37: Unknown | L37: S | M37: =IF(F37<13,"Child",IF(F37<20,"Teenager",IF(F37<40,"Adult",IF(F37<60,"Middle Age","Senior")))) -> Middle Age
A38: 37 | B38: 1 | C38: 3 | D38: Mamee, Mr. Hanna | E38: male | F38: 28 | G38: 0 | H38: 0 | I38: 2677 | J38: 7.2292 | K38: Unknown | L38: C | M38: =IF(F38<13,"Child",IF(F38<20,"Teenager",IF(F38<40,"Adult",IF(F38<60,"Middle Age","Senior")))) -> Adult
A39: 38 | B39: 0 | C39: 3 | D39: Cann, Mr. Ernest Charles | E39: male | F39: 21 | G39: 0 | H39: 0 | I39: A./5. 2152 | J39: 8.05 | K39: Unknown | L39: S | M39: =IF(F39<13,"Child",IF(F39<20,"Teenager",IF(F39<40,"Adult",IF(F39<60,"Middle Age","Senior")))) -> Adult
A40: 39 | B40: 0 | C40: 3 | D40: Vander Planke, Miss. Augusta Maria | E40: female | F40: 18 | G40: 2 | H40: 0 | I40: 345764 | J40: 18 | K40: Unknown | L40: S | M40: =IF(F40<13,"Child",IF(F40<20,"Teenager",IF(F40<40,"Adult",IF(F40<60,"Middle Age","Senior")))) -> Teenager
A41: 40 | B41: 1 | C41: 3 | D41: Nicola-Yarred, Miss. Jamila | E41: female | F41: 14 | G41: 1 | H41: 0 | I41: 2651 | J41: 11.2417 | K41: Unknown | L41: C | M41: =IF(F41<13,"Child",IF(F41<20,"Teenager",IF(F41<40,"Adult",IF(F41<60,"Middle Age","Senior")))) -> Teenager
A42: 41 | B42: 0 | C42: 3 | D42: Ahlin, Mrs. Johan (Johanna Persdotter Larsson) | E42: female | F42: 40 | G42: 1 | H42: 0 | I42: 7546 | J42: 9.475 | K42: Unknown | L42: S | M42: =IF(F42<13,"Child",IF(F42<20,"Teenager",IF(F42<40,"Adult",IF(F42<60,"Middle Age","Senior")))) -> Middle Age
A43: 42 | B43: 0 | C43: 2 | D43: Turpin, Mrs. William John Robert (Dorothy Ann Wonnacott) | E43: female | F43: 27 | G43: 1 | H43: 0 | I43: 11668 | J43: 21 | K43: Unknown | L43: S | M43: =IF(F43<13,"Child",IF(F43<20,"Teenager",IF(F43<40,"Adult",IF(F43<60,"Middle Age","Senior")))) -> Adult
A44: 43 | B44: 0 | C44: 3 | D44: Kraeff, Mr. Theodor | E44: male | F44: 28 | G44: 0 | H44: 0 | I44: 349253 | J44: 7.8958 | K44: Unknown | L44: C | M44: =IF(F44<13,"Child",IF(F44<20,"Teenager",IF(F44<40,"Adult",IF(F44<60,"Middle Age","Senior")))) -> Adult
...

Sheet Data Quality Check
A1: A | B1: B | D1: Minimum Age | E1: Maximum Age | F1: Minimum Fare | G1: Maximum Fare
A2: Column | B2: Missing Values | D2: =MIN(train!F2:F892) -> 0.42 | E2: =MAX(train!F2:F892) -> 80 | F2: =MIN(train!J2:J892) -> 0 | G2: =MAX(train!J2:J892) -> 512.3292
A3: PassengerId | B3: =COUNTBLANK(train!A2:A892) -> 0
A4: Survived | B4: =COUNTBLANK(train!B2:B892) -> 0
A5: Pclass | B5: =COUNTBLANK(train!C2:C892) -> 0
A6: Name | B6: =COUNTBLANK(train!F2:F892) -> 0
A7: Sex | B7: 0
A8: Age | B8: =COUNTBLANK(train!F2:F892) -> 0 | E8: Check | F8: Formula | G8: Expected Result
A9: SibSp | B9: =COUNTBLANK(train!G2:G892) -> 0 | E9: Missing Age | F9: =COUNTBLANK(train!F2:F892) -> 0 | G9: 0
A10: Parch | B10: =COUNTBLANK(train!H2:H892) -> 0 | E10: Missing Cabin | F10: =COUNTBLANK(train!K2:K892) -> 0 | G10: 0
A11: Ticket | B11: =COUNTBLANK(train!I2:I892) -> 0 | E11: Missing Embarked | F11: =COUNTBLANK(train!L2:L892) -> 0 | G11: 0
A12: Fare | B12: =COUNTBLANK(train!J2:J892) -> 0
A13: Cabin | B13: =COUNTBLANK(train!K2:K892) -> 0
A14: Embarked | B14: =COUNTBLANK(train!L2:L892) -> 0
A15: Duplicate Records | B15: 0 duplicates found
A21: Check | B21: Result
A22: Duplicate Records | B22: 0 duplicates found
A23: Sex consistency | B23: male, female only
A24: Embarked consistency | B24: S, C, Q only
A25: Pclass consistency | B25: 1, 2, 3 only
A26: Survived consistency | B26: 0, 1 only
